Workbook

Sheet Evaluaciones
A1: ID Empleado | B1: Nombre | C1: Cargo | D1: Departamento | E1: Evaluador (Jefe Directo) | F1: Fecha Evaluación | G1: Salario Base Mensual (COP) | H1: Cumplimiento de Objetivos | I1: Calidad del Trabajo | J1: Puntualidad/Asistencia | K1: Trabajo en Equipo | L1: Innovación | M1: Atención al Cliente | N1: Puntaje Promedio | O1: Calificación General | P1: Bono Anual % | Q1: Bono Anual (COP) | R1: Comentarios | S1: Recomendación
A2: E001 | B2: Laura Rojas Iguarán | C2: Gerente General | D2: Gerencia General | E2: Junta Directiva | F2: 45797 | G2: 16230000 | H2: 4 | I2: 4 | J2: 4 | K2: 4 | L2: 4 | M2: 4 | N2: =AVERAGE(H2:M2) -> 4 | O2: =IF(ROUND(N2,0)<=1,"Deficiente",IF(ROUND(N2,0)=2,"Bajo",IF(ROUND(N2,0)=3,"Satisfactorio",IF(ROUND(N2,0)=4,"Bueno","Excelente")))) -> Bueno | P2: =MAX(0,MIN(0.2,(N2-3)/2*0.2)) -> 0.1 | Q2: =G2*12*P2 -> 19476000 | R2: Sólido desempeño en el periodo, con buena disposición al aprendizaje. | S2: Ascenso
A3: E002 | B3: Eduardo Jiménez Torres | C3: Gerente de Ventas | D3: Ventas | E3: Laura Rojas Iguarán | F3: 45722 | G3: 8390000 | H3: 5 | I3: 5 | J3: 5 | K3: 5 | L3: 5 | M3: 5 | N3: =AVERAGE(H3:M3) -> 5 | O3: =IF(ROUND(N3,0)<=1,"Deficiente",IF(ROUND(N3,0)=2,"Bajo",IF(ROUND(N3,0)=3,"Satisfactorio",IF(ROUND(N3,0)=4,"Bueno","Excelente")))) -> Excelente | P3: =MAX(0,MIN(0.2,(N3-3)/2*0.2)) -> 0.2 | Q3: =G3*12*P3 -> 20136000 | R3: Excelente calidad de trabajo y liderazgo dentro de su equipo. | S3: Mantener
A4: E003 | B4: Diego Mendoza Redondo | C4: Supervisor Comercial | D4: Ventas | E4: Gerente de Ventas | F4: 45888 | G4: 4000000 | H4: 4 | I4: 4 | J4: 4 | K4: 5 | L4: 3 | M4: 3 | N4: =AVERAGE(H4:M4) -> 3.8333333 | O4: =IF(ROUND(N4,0)<=1,"Deficiente",IF(ROUND(N4,0)=2,"Bajo",IF(ROUND(N4,0)=3,"Satisfactorio",IF(ROUND(N4,0)=4,"Bueno","Excelente")))) -> Bueno | P4: =MAX(0,MIN(0.2,(N4-3)/2*0.2)) -> 0.083333333 | Q4: =G4*12*P4 -> 4000000 | R4: Muestra compromiso y calidad en su trabajo; buen ambiente de equipo. | S4: Mantener
A5: E004 | B5: Yeison Rojas Salcedo | C5: Supervisor Comercial | D5: Ventas | E5: Gerente de Ventas | F5: 45805 | G5: 4050000 | H5: 4 | I5: 4 | J5: 4 | K5: 3 | L5: 4 | M5: 5 | N5: =AVERAGE(H5:M5) -> 4 | O5: =IF(ROUND(N5,0)<=1,"Deficiente",IF(ROUND(N5,0)=2,"Bajo",IF(ROUND(N5,0)=3,"Satisfactorio",IF(ROUND(N5,0)=4,"Bueno","Excelente")))) -> Bueno | P5: =MAX(0,MIN(0.2,(N5-3)/2*0.2)) -> 0.1 | Q5: =G5*12*P5 -> 4860000 | R5: Sólido desempeño en el periodo, con buena disposición al aprendizaje. | S5: Mantener
A6: E005 | B6: Hernán Mendoza Morales | C6: Supervisor Comercial | D6: Ventas | E6: Gerente de Ventas | F6: 45812 | G6: 4580000 | H6: 4 | I6: 4 | J6: 4 | K6: 4 | L6: 4 | M6: 4 | N6: =AVERAGE(H6:M6) -> 4 | O6: =IF(ROUND(N6,0)<=1,"Deficiente",IF(ROUND(N6,0)=2,"Bajo",IF(ROUND(N6,0)=3,"Satisfactorio",IF(ROUND(N6,0)=4,"Bueno","Excelente")))) -> Bueno | P6: =MAX(0,MIN(0.2,(N6-3)/2*0.2)) -> 0.1 | Q6: =G6*12*P6 -> 5496000 | R6: Muestra compromiso y calidad en su trabajo; buen ambiente de equipo. | S6: Mantener
A7: E006 | B7: Nelson Castro Manjarrez | C7: Supervisor Comercial | D7: Ventas | E7: Gerente de Ventas | F7: 45829 | G7: 3590000 | H7: 5 | I7: 5 | J7: 4 | K7: 5 | L7: 4 | M7: 5 | N7: =AVERAGE(H7:M7) -> 4.6666667 | O7: =IF(ROUND(N7,0)<=1,"Deficiente",IF(ROUND(N7,0)=2,"Bajo",IF(ROUND(N7,0)=3,"Satisfactorio",IF(ROUND(N7,0)=4,"Bueno","Excelente")))) -> Excelente | P7: =MAX(0,MIN(0.2,(N7-3)/2*0.2)) -> 0.16666667 | Q7: =G7*12*P7 -> 7180000 | R7: Excelente calidad de trabajo y liderazgo dentro de su equipo. | S7: Mantener
A8: E007 | B8: Diana Redondo Pérez | C8: Asesor Comercial | D8: Ventas | E8: Diego Mendoza Redondo | F8: 45891 | G8: 2310000 | H8: 3 | I8: 2 | J8: 3 | K8: 4 | L8: 3 | M8: 3 | N8: =AVERAGE(H8:M8) -> 3 | O8: =IF(ROUND(N8,0)<=1,"Deficiente",IF(ROUND(N8,0)=2,"Bajo",IF(ROUND(N8,0)=3,"Satisfactorio",IF(ROUND(N8,0)=4,"Bueno","Excelente")))) -> Satisfactorio | P8: =MAX(0,MIN(0.2,(N8-3)/2*0.2)) -> 0 | Q8: =G8*12*P8 -> 0 | R8: Cumple con lo esperado en la mayoría de sus funciones; puede mejorar en algunos aspectos. | S8: Mantener
A9: E008 | B9: Ingrid Pacheco Martínez | C9: Asesor Comercial | D9: Ventas | E9: Yeison Rojas Salcedo | F9: 45803 | G9: 1560000 | H9: 4 | I9: 4 | J9: 4 | K9: 3 | L9: 4 | M9: 4 | N9: =AVERAGE(H9:M9) -> 3.8333333 | O9: =IF(ROUND(N9,0)<=1,"Deficiente",IF(ROUND(N9,0)=2,"Bajo",IF(ROUND(N9,0)=3,"Satisfactorio",IF(ROUND(N9,0)=4,"Bueno","Excelente")))) -> Bueno | P9: =MAX(0,MIN(0.2,(N9-3)/2*0.2)) -> 0.083333333 | Q9: =G9*12*P9 -> 1560000 | R9: Muestra compromiso y calidad en su trabajo; buen ambiente de equipo. | S9: Mantener
A10: E009 | B10: María Barros Morales | C10: Asesor Comercial | D10: Ventas | E10: Hernán Mendoza Morales | F10: 45732 | G10: 1580000 | H10: 4 | I10: 3 | J10: 3 | K10: 2 | L10: 3 | M10: 3 | N10: =AVERAGE(H10:M10) -> 3 | O10: =IF(ROUND(N10,0)<=1,"Deficiente",IF(ROUND(N10,0)=2,"Bajo",IF(ROUND(N10,0)=3,"Satisfactorio",IF(ROUND(N10,0)=4,"Bueno","Excelente")))) -> Satisfactorio | P10: =MAX(0,MIN(0.2,(N10-3)/2*0.2)) -> 0 | Q10: =G10*12*P10 -> 0 | R10: Desempeño estable; se recomienda reforzar innovación y proactividad. | S10: Capacitación
A11: E010 | B11: Diana Polo Redondo | C11: Asesor Comercial | D11: Ventas | E11: Nelson Castro Manjarrez | F11: 45700 | G11: 1460000 | H11: 4 | I11: 5 | J11: 5 | K11: 5 | L11: 5 | M11: 4 | N11: =AVERAGE(H11:M11) -> 4.6666667 | O11: =IF(ROUND(N11,0)<=1,"Deficiente",IF(ROUND(N11,0)=2,"Bajo",IF(ROUND(N11,0)=3,"Satisfactorio",IF(ROUND(N11,0)=4,"Bueno","Excelente")))) -> Excelente | P11: =MAX(0,MIN(0.2,(N11-3)/2*0.2)) -> 0.16666667 | Q11: =G11*12*P11 -> 2920000 | R11: Excelente calidad de trabajo y liderazgo dentro de su equipo. | S11: Mantener
A12: E011 | B12: Nelson López Muñoz | C12: Asesor Comercial | D12: Ventas | E12: Diego Mendoza Redondo | F12: 45882 | G12: 2440000 | H12: 2 | I12: 2 | J12: 2 | K12: 1 | L12: 1 | M12: 1 | N12: =AVERAGE(H12:M12) -> 1.5 | O12: =IF(ROUND(N12,0)<=1,"Deficiente",IF(ROUND(N12,0)=2,"Bajo",IF(ROUND(N12,0)=3,"Satisfactorio",IF(ROUND(N12,0)=4,"Bueno","Excelente")))) -> Bajo | P12: =MAX(0,MIN(0.2,(N12-3)/2*0.2)) -> 0 | Q12: =G12*12*P12 -> 0 | R12: Bajo desempeño generalizado; se requiere seguimiento cercano y capacitación urgente. | S12: PIP
A13: E012 | B13: Sergio Vargas Cervantes | C13: Asesor Comercial | D13: Ventas | E13: Yeison Rojas Salcedo | F13: 45667 | G13: 1520000 | H13: 4 | I13: 4 | J13: 4 | K13: 4 | L13: 5 | M13: 4 | N13: =AVERAGE(H13:M13) -> 4.1666667 | O13: =IF(ROUND(N13,0)<=1,"Deficiente",IF(ROUND(N13,0)=2,"Bajo",IF(ROUND(N13,0)=3,"Satisfactorio",IF(ROUND(N13,0)=4,"Bueno","Excelente")))) -> Bueno | P13: =MAX(0,MIN(0.2,(N13-3)/2*0.2)) -> 0.11666667 | Q13: =G13*12*P13 -> 2128000 | R13: Buen desempeño general; cumple consistentemente sus objetivos y metas. | S13: Mantener
... A188: E187 | B188: Ricardo Padilla Polo | C188: Analista de Mercadeo | D188: Mercadeo | E188: Jefe de Mercadeo | F188: 45691 | G188: 2090000 | H188: 3 | I188: 3 | J188: 3 | K188: 3 | L188: 3 | M188: 3 | N188: =AVERAGE(H188:M188) -> 3 | O188: =IF(ROUND(N188,0)<=1,"Deficiente",IF(ROUND(N188,0)=2,"Bajo",IF(ROUND(N188,0)=3,"Satisfactorio",IF(ROUND(N188,0)=4,"Bueno","Excelente")))) -> Satisfactorio | P188: =MAX(0,MIN(0.2,(N188-3)/2*0.2)) -> 0 | Q188: =G188*12*P188 -> 0 | R188: Cumple con lo esperado en la mayoría de sus funciones; puede mejorar en algunos aspectos. | S188: Mantener
A190: Nota: esta es la primera vez que se genera la nómina/organigrama de Andina Foods S.A.S. (187 empleados, 10 departamentos); queda como referencia para archivos futuros. Salario Base es un supuesto por nivel jerárquico (simulación para demo/analítica), no datos reales de nómina. Puntaje Promedio = AVERAGE(6 competencias). Calificación General = Puntaje Promedio redondeado, mapeado a la escala 1-5 (Deficiente/Bajo/Satisfactorio/Bueno/Excelente). Bono Anual % = escala lineal de 0% (puntaje ≤3) a 20% (puntaje=5). Bono Anual (COP) = Salario Base Mensual × 12 × Bono Anual %.

Sheet Resumen
A1: Resumen — Evaluaciones de Desempeño 2025 (Andina Foods S.A.S.)
A3: Total empleados evaluados | B3: =COUNTA(Evaluaciones!A2:A188) -> 187
A5: Excelente (# empleados) | B5: =COUNTIF(Evaluaciones!O2:O188,"Excelente") -> 43
A6: Bueno (# empleados) | B6: =COUNTIF(Evaluaciones!O2:O188,"Bueno") -> 91
A7: Satisfactorio (# empleados) | B7: =COUNTIF(Evaluaciones!O2:O188,"Satisfactorio") -> 37
A8: Bajo (# empleados) | B8: =COUNTIF(Evaluaciones!O2:O188,"Bajo") -> 14
A9: Deficiente (# empleados) | B9: =COUNTIF(Evaluaciones!O2:O188,"Deficiente") -> 2
A10: % Bueno + Excelente | B10: =(B5+B6)/B3 -> 0.71657754
A11: % Satisfactorio | B11: =B7/B3 -> 0.19786096
A12: % Bajo + Deficiente | B12: =(B8+B9)/B3 -> 0.085561497
A14: Puntaje promedio general | B14: =AVERAGE(Evaluaciones!N2:N188) -> 3.8368984
A15: Puntaje promedio — Gerencia/Jefaturas | B15: =AVERAGEIF(Evaluaciones!C2:C188,"*Gerente*",Evaluaciones!N2:N188) -> 4.5
A17: Empleados con recomendación Ascenso | B17: =COUNTIF(Evaluaciones!S2:S188,"Ascenso") -> 25
A18: Empleados con recomendación Mantener | B18: =COUNTIF(Evaluaciones!S2:S188,"Mantener") -> 131
A19: Empleados con recomendación Capacitación | B19: =COUNTIF(Evaluaciones!S2:S188,"Capacitación") -> 22
A20: Empleados con recomendación PIP | B20: =COUNTIF(Evaluaciones!S2:S188,"PIP") -> 9
A22: Costo total de bonos 2025 (COP) | B22: =SUM(Evaluaciones!Q2:Q188) -> 608370000
A23: Bono promedio por empleado (COP) | B23: =AVERAGE(Evaluaciones!Q2:Q188) -> 3253315.5
A25: Top 10 Mejores Empleados (Puntaje Promedio)
A26: ID | B26: Nombre | C26: Cargo | D26: Departamento | E26: Puntaje
A27: =Evaluaciones!A3 -> E002 | B27: =Evaluaciones!B3 -> Eduardo Jiménez Torres | C27: =Evaluaciones!C3 -> Gerente de Ventas | D27: =Evaluaciones!D3 -> Ventas | E27: =Evaluaciones!N3 -> 5
A28: =Evaluaciones!A15 -> E014 | B28: =Evaluaciones!B15 -> Andrés Vargas Vega | C28: =Evaluaciones!C15 -> Asesor Comercial | D28: =Evaluaciones!D15 -> Ventas | E28: =Evaluaciones!N15 -> 5
A29: =Evaluaciones!A38 -> E037 | B29: =Evaluaciones!B38 -> Diego Barros Castillo | C29: =Evaluaciones!C38 -> Asesor Comercial | D29: =Evaluaciones!D38 -> Ventas | E29: =Evaluaciones!N38 -> 5
A30: =Evaluaciones!A61 -> E060 | B30: =Evaluaciones!B61 -> María Núñez Romero | C30: =Evaluaciones!C61 -> Jefe de Logística | D30: =Evaluaciones!D61 -> Logística y Distribución | E30: =Evaluaciones!N61 -> 5
A31: =Evaluaciones!A62 -> E061 | B31: =Evaluaciones!B62 -> Yolanda Vargas Torres | C31: =Evaluaciones!C62 -> Supervisor de Ruta | D31: =Evaluaciones!D62 -> Logística y Distribución | E31: =Evaluaciones!N62 -> 5
A32: =Evaluaciones!A63 -> E062 | B32: =Evaluaciones!B63 -> Álvaro Martínez López | C32: =Evaluaciones!C63 -> Supervisor de Ruta | D32: =Evaluaciones!D63 -> Logística y Distribución | E32: =Evaluaciones!N63 -> 5
A33: =Evaluaciones!A104 -> E103 | B33: =Evaluaciones!B104 -> Tatiana Rojas Sánchez | C33: =Evaluaciones!C104 -> Supervisor de Bodega | D33: =Evaluaciones!D104 -> Bodega y Almacén | E33: =Evaluaciones!N104 -> 5
A34: =Evaluaciones!A117 -> E116 | B34: =Evaluaciones!B117 -> Freddy Pérez Cárdenas | C34: =Evaluaciones!C117 -> Auxiliar de Bodega | D34: =Evaluaciones!D117 -> Bodega y Almacén | E34: =Evaluaciones!N117 -> 5
A35: =Evaluaciones!A138 -> E137 | B35: =Evaluaciones!B138 -> Yolanda Vargas Medina | C35: =Evaluaciones!C138 -> Jefe de Servicio al Cliente | D35: =Evaluaciones!D138 -> Servicio al Cliente | E35: =Evaluaciones!N138 -> 5
A36: =Evaluaciones!A139 -> E138 | B36: =Evaluaciones!B139 -> Luis Iguarán García | C36: =Evaluaciones!C139 -> Supervisor de Servicio al Cliente | D36: =Evaluaciones!D139 -> Servicio al Cliente | E36: =Evaluaciones!N139 -> 5
A38: Empleados con Recomendación Capacitación o PIP
A39: ID | B39: Nombre | C39: Cargo | D39: Departamento | E39: Recomendación
A40: =Evaluaciones!A12 -> E011 | B40: =Evaluaciones!B12 -> Nelson López Muñoz | C40: =Evaluaciones!C12 -> Asesor Comercial | D40: =Evaluaciones!D12 -> Ventas | E40: =Evaluaciones!S12 -> PIP
A41: =Evaluaciones!A80 -> E079 | B41: =Evaluaciones!B80 -> Luisa Suárez Vargas | C41: =Evaluaciones!C80 -> Conductor / Auxiliar de Reparto | D41: =Evaluaciones!D80 -> Logística y Distribución | E41: =Evaluaciones!S80 -> PIP
A42: =Evaluaciones!A174 -> E173 | B42: =Evaluaciones!B174 -> Fernando Iguarán Castillo | C42: =Evaluaciones!C174 -> Analista de Recursos Humanos | D42: =Evaluaciones!D174 -> Recursos Humanos | E42: =Evaluaciones!S174 -> PIP
A43: =Evaluaciones!A18 -> E017 | B43: =Evaluaciones!B18 -> Yesenia Torres Redondo | C43: =Evaluaciones!C18 -> Asesor Comercial | D43: =Evaluaciones!D18 -> Ventas | E43: =Evaluaciones!S18 -> PIP
A44: =Evaluaciones!A59 -> E058 | B44: =Evaluaciones!B59 -> Mauricio Cantillo García | C44: =Evaluaciones!C59 -> Asesor Comercial | D44: =Evaluaciones!D59 -> Ventas | E44: =Evaluaciones!S59 -> PIP
A45: =Evaluaciones!A69 -> E068 | B45: =Evaluaciones!B69 -> Diana Ramírez Torres | C45: =Evaluaciones!C69 -> Conductor / Auxiliar de Reparto | D45: =Evaluaciones!D69 -> Logística y Distribución | E45: =Evaluaciones!S69 -> PIP
A46: =Evaluaciones!A79 -> E078 | B46: =Evaluaciones!B79 -> Ingrid Núñez Martínez | C46: =Evaluaciones!C79 -> Conductor / Auxiliar de Reparto | D46: =Evaluaciones!D79 -> Logística y Distribución | E46: =Evaluaciones!S79 -> PIP
A47: =Evaluaciones!A135 -> E134 | B47: =Evaluaciones!B135 -> Iván Castro Salcedo | C47: =Evaluaciones!C135 -> Auxiliar de Bodega | D47: =Evaluaciones!D135 -> Bodega y Almacén | E47: =Evaluaciones!S135 -> PIP
...
