Workbook

Sheet Detalle
A1: ID | B1: Fecha Registro | C1: Tipo | D1: Categoría | E1: Cliente/Interno | F1: Descripción | G1: Departamento Responsable | H1: Prioridad | I1: Estado | J1: Causa Raíz | K1: Acción Correctiva | L1: Fecha Resolución | M1: Días para Resolver | N1: Costo Impacto (COP) | O1: Seguimiento
A2: PQRS-001 | B2: 45660 | C2: Reclamo | D2: Entrega/Logística | E2: Tienda El Trebol | F2: Los empaques llegaron golpeados por mal manejo durante el transporte. | G2: Logística y Distribución | H2: Alta | I2: Resuelto | J2: Ruta de reparto mal planificada para la zona. | K2: Se reenvió el faltante en un despacho adicional sin costo. | L2: 45689 | M2: =IF(L2="","",L2-B2) -> 29 | N2: 1939000 | O2: Sí
A3: PQRS-002 | B3: 45665 | C3: Petición | D3: Facturación | E3: Panadería San Fernando | F3: La factura tiene un valor distinto al acordado en el pedido. | G3: Finanzas y Contabilidad | H3: Crítica | I3: Abierto | M3: =IF(L3="","",L3-B3) | N3: 0 | O3: Sí
A4: PQRS-003 | B4: 45668 | C4: Sugerencia | D4: Entrega/Logística | E4: Deposito San Roque | F4: Se solicita ampliar la frecuencia de reparto para la zona. | G4: Logística y Distribución | H4: Baja | I4: En proceso | M4: =IF(L4="","",L4-B4) | N4: 0 | O4: Sí
A5: PQRS-004 | B5: 45670 | C5: Queja | D5: Entrega/Logística | E5: Supermercado Ahorro Costeño | F5: Los empaques llegaron golpeados por mal manejo durante el transporte. | G5: Logística y Distribución | H5: Alta | I5: Resuelto | J5: Error en el alistamiento de pedido en bodega. | K5: Se reasignó la ruta y se coordinó nuevo horario con el cliente. | L5: 45698 | M5: =IF(L5="","",L5-B5) -> 28 | N5: 1122000 | O5: Sí
A6: PQRS-005 | B6: 45676 | C6: Reclamo | D6: Facturación | E6: Hospital Del Caribe | F6: El cliente no ha recibido la factura electrónica del pedido. | G6: Finanzas y Contabilidad | H6: Media | I6: En proceso | J6: Falla en el envío automático de la factura electrónica. | M6: =IF(L6="","",L6-B6) | N6: 0 | O6: Sí
A7: PQRS-006 | B7: 45677 | C7: Reclamo | D7: Calidad producto | E7: Tienda El Faro | F7: El cliente reporta sabor o textura distinta a la habitual del producto. | G7: Bodega y Almacén | H7: Alta | I7: Resuelto | J7: Condiciones de almacenamiento inadecuadas (humedad/temperatura). | K7: Se ajustaron las condiciones de almacenamiento en la bodega regional. | L7: 45683 | M7: =IF(L7="","",L7-B7) -> 6 | N7: 0 | O7: Sí
A8: PQRS-007 | B8: 45677 | C8: Sugerencia | D8: Servicio | E8: Autoservicios La Bonanza | F8: El cliente solicita más información sobre el catálogo de productos. | G8: Servicio al Cliente | H8: Baja | I8: Resuelto | L8: 45703 | M8: =IF(L8="","",L8-B8) -> 26 | N8: 0 | O8: Sí
A9: PQRS-008 | B9: 45679 | C9: Petición | D9: Entrega/Logística | E9: Casino La Sagrada Familia | F9: El pedido llegó incompleto; faltaron varias referencias de la orden. | G9: Logística y Distribución | H9: Baja | I9: Resuelto | L9: 45691 | M9: =IF(L9="","",L9-B9) -> 12 | N9: 0 | O9: Sí
A10: PQRS-009 | B10: 45685 | C10: Sugerencia | D10: Calidad producto | E10: Supermercado La Economía | F10: El producto llegó próximo a su fecha de vencimiento. | G10: Bodega y Almacén | H10: Alta | I10: Resuelto | L10: 45693 | M10: =IF(L10="","",L10-B10) -> 8 | N10: 0 | O10: Sí
A11: PQRS-010 | B11: 45686 | C11: Petición | D11: Entrega/Logística | E11: Hipermercado La 15 | F11: El pedido llegó incompleto; faltaron varias referencias de la orden. | G11: Logística y Distribución | H11: Baja | I11: Resuelto | L11: 45711 | M11: =IF(L11="","",L11-B11) -> 25 | N11: 0 | O11: Sí
A12: PQRS-011 | B12: 45686 | C12: Reclamo | D12: Entrega/Logística | E12: Autoservicio Don Pedro | F12: La entrega llegó con más de 3 días de retraso frente a lo acordado. | G12: Logística y Distribución | H12: Alta | I12: Resuelto | J12: Congestión vial no prevista en la planeación de ruta. | K12: Se realizó reposición del producto dañado y se ajustó el embalaje. | L12: 45706 | M12: =IF(L12="","",L12-B12) -> 20 | N12: 781000 | O12: Sí
A13: PQRS-012 | B13: 45689 | C13: Queja | D13: Entrega/Logística | E13: Fundación La Sagrada Familia | F13: La entrega llegó con más de 3 días de retraso frente a lo acordado. | G13: Logística y Distribución | H13: Media | I13: En proceso | J13: Congestión vial no prevista en la planeación de ruta. | M13: =IF(L13="","",L13-B13) | N13: 2423000 | O13: Sí
A14: PQRS-013 | B14: 45689 | C14: Petición | D14: Entrega/Logística | E14: Minimercado Don Pedro | F14: Los empaques llegaron golpeados por mal manejo durante el transporte. | G14: Logística y Distribución | H14: Baja | I14: Cerrado | L14: 45713 | M14: =IF(L14="","",L14-B14) -> 24 | N14: 0 | O14: Sí
A15: PQRS-014 | B15: 45692 | C15: Sugerencia | D15: Otra | E15: Hipermercado La 15 | F15: Solicitud de información sobre el proceso de vinculación como proveedor. | G15: Gerencia General | H15: Baja | I15: Cerrado | L15: 45703 | M15: =IF(L15="","",L15-B15) -> 11 | N15: 0 | O15: Sí
A16: PQRS-015 | B16: 45693 | C16: Petición | D16: Facturación | E16: Minimercado San Judas | F16: Se cobró un producto que no fue entregado. | G16: Finanzas y Contabilidad | H16: Baja | I16: Resuelto | L16: 45696 | M16: =IF(L16="","",L16-B16) -> 3 | N16: 0 | O16: Sí
A17: PQRS-016 | B17: 45694 | C17: Queja | D17: Otra | E17: Deposito Las Delicias | F17: Solicitud de visita comercial para evaluar nuevas líneas de producto. | G17: Gerencia General | H17: Media | I17: Resuelto | J17: Solicitud de información, no aplica causa raíz. | K17: Se brindó la información solicitada al cliente. | L17: 45708 | M17: =IF(L17="","",L17-B17) -> 14 | N17: 0 | O17: No
A18: PQRS-017 | B18: 45697 | C18: Queja | D18: Entrega/Logística | E18: Cafetería Empresarial La Popa | F18: El pedido llegó incompleto; faltaron varias referencias de la orden. | G18: Logística y Distribución | H18: Media | I18: En proceso | J18: Congestión vial no prevista en la planeación de ruta. | M18: =IF(L18="","",L18-B18) | N18: 366000 | O18: Sí
A19: PQRS-018 | B19: 45704 | C19: Queja | D19: Entrega/Logística | E19: Autoservicio La Costeña | F19: Los empaques llegaron golpeados por mal manejo durante el transporte. | G19: Logística y Distribución | H19: Alta | I19: En proceso | J19: Personal de reparto nuevo sin inducción completa. | M19: =IF(L19="","",L19-B19) | N19: 2451000 | O19: Sí
A20: PQRS-019 | B20: 45704 | C20: Reclamo | D20: Entrega/Logística | E20: Clínica Nuestra Señora del Carmen | F20: El vehículo de reparto llegó fuera del horario pactado con la tienda. | G20: Logística y Distribución | H20: Alta | I20: Resuelto | J20: Ruta de reparto mal planificada para la zona. | K20: Se reforzó el checklist de alistamiento antes de despacho. | L20: 45721 | M20: =IF(L20="","",L20-B20) -> 17 | N20: 0 | O20: No
A21: PQRS-020 | B21: 45711 | C21: Queja | D21: Calidad producto | E21: Interno - Logística y Distribución | F21: Se identificó un lote con etiquetado incorrecto de fecha de vencimiento. | G21: Bodega y Almacén | H21: Crítica | I21: Resuelto | J21: Condiciones de almacenamiento inadecuadas (humedad/temperatura). | K21: Se cambió el producto y se reforzó la rotación FIFO en bodega. | L21: 45736 | M21: =IF(L21="","",L21-B21) -> 25 | N21: 1706000 | O21: No
A22: PQRS-021 | B22: 45712 | C22: Reclamo | D22: Calidad producto | E22: Autoservicios Mercar | F22: El producto llegó próximo a su fecha de vencimiento. | G22: Bodega y Almacén | H22: Alta | I22: Resuelto | J22: Condiciones de almacenamiento inadecuadas (humedad/temperatura). | K22: Se retiró el lote afectado y se notificó al proveedor. | L22: 45716 | M22: =IF(L22="","",L22-B22) -> 4 | N22: 0 | O22: No
A23: PQRS-022 | B23: 45712 | C23: Sugerencia | D23: Calidad producto | E23: Autoservicio La Costeña | F23: Se solicita revisar la calidad del último lote despachado. | G23: Bodega y Almacén | H23: Alta | I23: Resuelto | L23: 45735 | M23: =IF(L23="","",L23-B23) -> 23 | N23: 0 | O23: Sí
A24: PQRS-023 | B24: 45716 | C24: Reclamo | D24: Servicio | E24: Hipermercado El Cacique | F24: No se dio seguimiento oportuno a una solicitud anterior. | G24: Servicio al Cliente | H24: Media | I24: Resuelto | J24: Sobrecarga de casos en el equipo de servicio al cliente. | K24: Se agendó capacitación para el equipo de servicio al cliente. | L24: 45736 | M24: =IF(L24="","",L24-B24) -> 20 | N24: 0 | O24: Sí
A25: PQRS-024 | B25: 45721 | C25: Queja | D25: Entrega/Logística | E25: Hipermercado Ahorro Costeño | F25: El pedido llegó incompleto; faltaron varias referencias de la orden. | G25: Logística y Distribución | H25: Alta | I25: Abierto | J25: Personal de reparto nuevo sin inducción completa. | M25: =IF(L25="","",L25-B25) | N25: 0 | O25: No
A26: PQRS-025 | B26: 45722 | C26: Reclamo | D26: Entrega/Logística | E26: Clínica San José | F26: Se solicita ampliar la frecuencia de reparto para la zona. | G26: Logística y Distribución | H26: Baja | I26: Cerrado | J26: Error en el alistamiento de pedido en bodega. | K26: Se realizó reposición del producto dañado y se ajustó el embalaje. | L26: 45751 | M26: =IF(L26="","",L26-B26) -> 29 | N26: 0 | O26: Sí
A27: PQRS-026 | B27: 45723 | C27: Reclamo | D27: Entrega/Logística | E27: Hipermercado La Economía | F27: Se recibió mercancía de una referencia distinta a la solicitada. | G27: Logística y Distribución | H27: Media | I27: Resuelto | J27: Error en el alistamiento de pedido en bodega. | K27: Se realizó reposición del producto dañado y se ajustó el embalaje. | L27: 45746 | M27: =IF(L27="","",L27-B27) -> 23 | N27: 0 | O27: Sí
A28: PQRS-027 | B28: 45728 | C28: Queja | D28: Entrega/Logística | E28: Autoservicios Central | F28: Los empaques llegaron golpeados por mal manejo durante el transporte. | G28: Logística y Distribución | H28: Media | I28: En proceso | J28: Congestión vial no prevista en la planeación de ruta. | M28: =IF(L28="","",L28-B28) | N28: 0 | O28: Sí
A29: PQRS-028 | B29: 45738 | C29: Reclamo | D29: Servicio | E29: Tienda El Paisa | F29: El cliente reporta demora en la respuesta del asesor comercial. | G29: Servicio al Cliente | H29: Media | I29: Resuelto | J29: Falta de protocolo claro de respuesta a clientes. | K29: Se reforzó el protocolo de atención con el equipo comercial. | L29: 45740 | M29: =IF(L29="","",L29-B29) -> 2 | N29: 0 | O29: Sí
A30: PQRS-029 | B30: 45740 | C30: Reclamo | D30: Entrega/Logística | E30: Autoservicio San Judas | F30: El pedido llegó incompleto; faltaron varias referencias de la orden. | G30: Logística y Distribución | H30: Media | I30: En proceso | J30: Falla de comunicación entre bodega y transporte. | M30: =IF(L30="","",L30-B30) | N30: 2327000 | O30: Sí
A31: PQRS-030 | B31: 45743 | C31: Queja | D31: Calidad producto | E31: Colegio El Bosque | F31: El cliente reporta presencia de cuerpo extraño en el producto. | G31: Bodega y Almacén | H31: Alta | I31: En proceso | J31: Rotación de inventario (FIFO) no aplicada correctamente en bodega. | M31: =IF(L31="","",L31-B31) | N31: 0 | O31: Sí
A32: PQRS-031 | B32: 45745 | C32: Queja | D32: Entrega/Logística | E32: Interno - Bodega y Almacén | F32: Los empaques llegaron golpeados por mal manejo durante el transporte. | G32: Logística y Distribución | H32: Media | I32: Resuelto | J32: Personal de reparto nuevo sin inducción completa. | K32: Se realizó reposición del producto dañado y se ajustó el embalaje. | L32: 45769 | M32: =IF(L32="","",L32-B32) -> 24 | N32: 0 | O32: Sí
A33: PQRS-032 | B33: 45746 | C33: Queja | D33: Entrega/Logística | E33: Cafetería Empresarial La Popa | F33: El vehículo de reparto llegó fuera del horario pactado con la tienda. | G33: Logística y Distribución | H33: Media | I33: Resuelto | J33: Personal de reparto nuevo sin inducción completa. | K33: Se reasignó la ruta y se coordinó nuevo horario con el cliente. | L33: 45756 | M33: =IF(L33="","",L33-B33) -> 10 | N33: 0 | O33: Sí
A34: PQRS-033 | B34: 45746 | C34: Reclamo | D34: Facturación | E34: Hipermercado La Economía | F34: Existe una diferencia entre el precio pactado y el facturado. | G34: Finanzas y Contabilidad | H34: Media | I34: En proceso | J34: Error de digitación en el sistema de facturación. | M34: =IF(L34="","",L34-B34) | N34: 0 | O34: Sí
A35: PQRS-034 | B35: 45746 | C35: Reclamo | D35: Servicio | E35: Autoservicios La 15 | F35: No se dio seguimiento oportuno a una solicitud anterior. | G35: Servicio al Cliente | H35: Media | I35: Resuelto | J35: Sobrecarga de casos en el equipo de servicio al cliente. | K35: Se reforzó el protocolo de atención con el equipo comercial. | L35: 45757 | M35: =IF(L35="","",L35-B35) -> 11 | N35: 0 | O35: Sí
A36: PQRS-035 | B36: 45747 | C36: Petición | D36: Otra | E36: Hospital Del Caribe | F36: Comentario general sobre la experiencia de compra con la empresa. | G36: Gerencia General | H36: Media | I36: Cerrado | L36: 45772 | M36: =IF(L36="","",L36-B36) -> 25 | N36: 0 | O36: Sí
A37: PQRS-036 | B37: 45748 | C37: Sugerencia | D37: Entrega/Logística | E37: Tienda La 84 | F37: La entrega llegó con más de 3 días de retraso frente a lo acordado. | G37: Logística y Distribución | H37: Baja | I37: Resuelto | L37: 45774 | M37: =IF(L37="","",L37-B37) -> 26 | N37: 0 | O37: Sí
A38: PQRS-037 | B38: 45750 | C38: Reclamo | D38: Entrega/Logística | E38: Interno - Logística y Distribución | F38: Se recibió mercancía de una referencia distinta a la solicitada. | G38: Logística y Distribución | H38: Alta | I38: Cerrado | J38: Personal de reparto nuevo sin inducción completa. | K38: Se reasignó la ruta y se coordinó nuevo horario con el cliente. | L38: 45768 | M38: =IF(L38="","",L38-B38) -> 18 | N38: 867000 | O38: Sí
A39: PQRS-038 | B39: 45752 | C39: Reclamo | D39: Entrega/Logística | E39: Interno - Servicio al Cliente | F39: El pedido llegó incompleto; faltaron varias referencias de la orden. | G39: Logística y Distribución | H39: Alta | I39: En proceso | J39: Ruta de reparto mal planificada para la zona. | M39: =IF(L39="","",L39-B39) | N39: 0 | O39: No
A40: PQRS-039 | B40: 45753 | C40: Reclamo | D40: Calidad producto | E40: Panadería San Fernando | F40: Llegaron unidades con el empaque deteriorado por humedad. | G40: Bodega y Almacén | H40: Media | I40: En proceso | J40: Rotación de inventario (FIFO) no aplicada correctamente en bodega. | M40: =IF(L40="","",L40-B40) | N40: 0 | O40: Sí
...

Sheet Resumen
A1: Resumen — PQRS y Control de Calidad 2025 (Andina Foods S.A.S.)
A3: Total de casos registrados | B3: =COUNTA(Detalle!A2:A101) -> 100
A5: Peticiones | B5: =COUNTIF(Detalle!C2:C101,"Petición") -> 15
A6: Quejas | B6: =COUNTIF(Detalle!C2:C101,"Queja") -> 34
A7: Reclamos | B7: =COUNTIF(Detalle!C2:C101,"Reclamo") -> 41
A8: Sugerencias | B8: =COUNTIF(Detalle!C2:C101,"Sugerencia") -> 10
A10: Abiertos | B10: =COUNTIF(Detalle!I2:I101,"Abierto") -> 2
A11: En proceso | B11: =COUNTIF(Detalle!I2:I101,"En proceso") -> 15
A12: Resueltos | B12: =COUNTIF(Detalle!I2:I101,"Resuelto") -> 63
A13: Cerrados | B13: =COUNTIF(Detalle!I2:I101,"Cerrado") -> 20
A14: % Resuelto + Cerrado | B14: =(B12+B13)/B3 -> 0.83
A15: % Abierto + En proceso | B15: =(B10+B11)/B3 -> 0.17
A17: Costo total de impacto (COP) | B17: =SUM(Detalle!N2:N101) -> 24385000
A18: Días promedio de resolución (casos resueltos) | B18: =AVERAGEIF(Detalle!I2:I101,"Resuelto",Detalle!M2:M101) -> 15.539683
A20: Casos sin seguimiento y aún abiertos/en proceso (alerta) | B20: =SUMPRODUCT((Detalle!I2:I101<>"Resuelto")*(Detalle!I2:I101<>"Cerrado")*(Detalle!O2:O101="No")) -> 3
A22: Promedio de Días de Resolución por Categoría
A23: Categoría | B23: # Casos | C23: # Resueltos/Cerrados | D23: Días Promedio Resolución | E23: Costo Impacto (COP)
A24: Entrega/Logística | B24: =COUNTIF(Detalle!D2:D101,"Entrega/Logística") -> 48 | C24: =COUNTIFS(Detalle!D2:D101,"Entrega/Logística",Detalle!I2:I101,"Resuelto")+COUNTIFS(Detalle!D2:D101,"Entrega/Logística",Detalle!I2:I101,"Cerrado") -> 39 | D24: =IFERROR((SUMIFS(Detalle!M2:M101,Detalle!D2:D101,"Entrega/Logística",Detalle!I2:I101,"Resuelto")+SUMIFS(Detalle!M2:M101,Detalle!D2:D101,"Entrega/Logística",Detalle!I2:I101,"Cerrado"))/C24,0) -> 17.461538 | E24: =SUMIF(Detalle!D2:D101,"Entrega/Logística",Detalle!N2:N101) -> 18532000
A25: Calidad producto | B25: =COUNTIF(Detalle!D2:D101,"Calidad producto") -> 19 | C25: =COUNTIFS(Detalle!D2:D101,"Calidad producto",Detalle!I2:I101,"Resuelto")+COUNTIFS(Detalle!D2:D101,"Calidad producto",Detalle!I2:I101,"Cerrado") -> 17 | D25: =IFERROR((SUMIFS(Detalle!M2:M101,Detalle!D2:D101,"Calidad producto",Detalle!I2:I101,"Resuelto")+SUMIFS(Detalle!M2:M101,Detalle!D2:D101,"Calidad producto",Detalle!I2:I101,"Cerrado"))/C25,0) -> 12.117647 | E25: =SUMIF(Detalle!D2:D101,"Calidad producto",Detalle!N2:N101) -> 5853000
A26: Facturación | B26: =COUNTIF(Detalle!D2:D101,"Facturación") -> 14 | C26: =COUNTIFS(Detalle!D2:D101,"Facturación",Detalle!I2:I101,"Resuelto")+COUNTIFS(Detalle!D2:D101,"Facturación",Detalle!I2:I101,"Cerrado") -> 9 | D26: =IFERROR((SUMIFS(Detalle!M2:M101,Detalle!D2:D101,"Facturación",Detalle!I2:I101,"Resuelto")+SUMIFS(Detalle!M2:M101,Detalle!D2:D101,"Facturación",Detalle!I2:I101,"Cerrado"))/C26,0) -> 10.333333 | E26: =SUMIF(Detalle!D2:D101,"Facturación",Detalle!N2:N101) -> 0
A27: Servicio | B27: =COUNTIF(Detalle!D2:D101,"Servicio") -> 14 | C27: =COUNTIFS(Detalle!D2:D101,"Servicio",Detalle!I2:I101,"Resuelto")+COUNTIFS(Detalle!D2:D101,"Servicio",Detalle!I2:I101,"Cerrado") -> 14 | D27: =IFERROR((SUMIFS(Detalle!M2:M101,Detalle!D2:D101,"Servicio",Detalle!I2:I101,"Resuelto")+SUMIFS(Detalle!M2:M101,Detalle!D2:D101,"Servicio",Detalle!I2:I101,"Cerrado"))/C27,0) -> 14.785714 | E27: =SUMIF(Detalle!D2:D101,"Servicio",Detalle!N2:N101) -> 0
A28: Otra | B28: =COUNTIF(Detalle!D2:D101,"Otra") -> 5 | C28: =COUNTIFS(Detalle!D2:D101,"Otra",Detalle!I2:I101,"Resuelto")+COUNTIFS(Detalle!D2:D101,"Otra",Detalle!I2:I101,"Cerrado") -> 4 | D28: =IFERROR((SUMIFS(Detalle!M2:M101,Detalle!D2:D101,"Otra",Detalle!I2:I101,"Resuelto")+SUMIFS(Detalle!M2:M101,Detalle!D2:D101,"Otra",Detalle!I2:I101,"Cerrado"))/C28,0) -> 18.75 | E28: =SUMIF(Detalle!D2:D101,"Otra",Detalle!N2:N101) -> 0
A30: Tendencia Mensual de Casos (Enero-Agosto 2025)
A31: Mes | B31: # Casos Registrados | C31: # Reclamos | D31: # Quejas | E31: Costo Impacto (COP)
A32: Enero | B32: =SUMPRODUCT((TEXT(Detalle!B2:B101,"YYYY-MM")="2025-01")*1) -> 11 | C32: =SUMPRODUCT((TEXT(Detalle!B2:B101,"YYYY-MM")="2025-01")*(Detalle!C2:C101="Reclamo")) -> 4 | D32: =SUMPRODUCT((TEXT(Detalle!B2:B101,"YYYY-MM")="2025-01")*(Detalle!C2:C101="Queja")) -> 1 | E32: =SUMPRODUCT((TEXT(Detalle!B2:B101,"YYYY-MM")="2025-01")*Detalle!N2:N101) -> 3842000
A33: Febrero | B33: =SUMPRODUCT((TEXT(Detalle!B2:B101,"YYYY-MM")="2025-02")*1) -> 12 | C33: =SUMPRODUCT((TEXT(Detalle!B2:B101,"YYYY-MM")="2025-02")*(Detalle!C2:C101="Reclamo")) -> 3 | D33: =SUMPRODUCT((TEXT(Detalle!B2:B101,"YYYY-MM")="2025-02")*(Detalle!C2:C101="Queja")) -> 5 | E33: =SUMPRODUCT((TEXT(Detalle!B2:B101,"YYYY-MM")="2025-02")*Detalle!N2:N101) -> 6946000
A34: Marzo | B34: =SUMPRODUCT((TEXT(Detalle!B2:B101,"YYYY-MM")="2025-03")*1) -> 12 | C34: =SUMPRODUCT((TEXT(Detalle!B2:B101,"YYYY-MM")="2025-03")*(Detalle!C2:C101="Reclamo")) -> 6 | D34: =SUMPRODUCT((TEXT(Detalle!B2:B101,"YYYY-MM")="2025-03")*(Detalle!C2:C101="Queja")) -> 5 | E34: =SUMPRODUCT((TEXT(Detalle!B2:B101,"YYYY-MM")="2025-03")*Detalle!N2:N101) -> 2327000
A35: Abril | B35: =SUMPRODUCT((TEXT(Detalle!B2:B101,"YYYY-MM")="2025-04")*1) -> 13 | C35: =SUMPRODUCT((TEXT(Detalle!B2:B101,"YYYY-MM")="2025-04")*(Detalle!C2:C101="Reclamo")) -> 6 | D35: =SUMPRODUCT((TEXT(Detalle!B2:B101,"YYYY-MM")="2025-04")*(Detalle!C2:C101="Queja")) -> 6 | E35: =SUMPRODUCT((TEXT(Detalle!B2:B101,"YYYY-MM")="2025-04")*Detalle!N2:N101) -> 2056000
A36: Mayo | B36: =SUMPRODUCT((TEXT(Detalle!B2:B101,"YYYY-MM")="2025-05")*1) -> 13 | C36: =SUMPRODUCT((TEXT(Detalle!B2:B101,"YYYY-MM")="2025-05")*(Detalle!C2:C101="Reclamo")) -> 6 | D36: =SUMPRODUCT((TEXT(Detalle!B2:B101,"YYYY-MM")="2025-05")*(Detalle!C2:C101="Queja")) -> 4 | E36: =SUMPRODUCT((TEXT(Detalle!B2:B101,"YYYY-MM")="2025-05")*Detalle!N2:N101) -> 3992000
A37: Junio | B37: =SUMPRODUCT((TEXT(Detalle!B2:B101,"YYYY-MM")="2025-06")*1) -> 12 | C37: =SUMPRODUCT((TEXT(Detalle!B2:B101,"YYYY-MM")="2025-06")*(Detalle!C2:C101="Reclamo")) -> 3 | D37: =SUMPRODUCT((TEXT(Detalle!B2:B101,"YYYY-MM")="2025-06")*(Detalle!C2:C101="Queja")) -> 3 | E37: =SUMPRODUCT((TEXT(Detalle!B2:B101,"YYYY-MM")="2025-06")*Detalle!N2:N101) -> 1149000
A38: Julio | B38: =SUMPRODUCT((TEXT(Detalle!B2:B101,"YYYY-MM")="2025-07")*1) -> 13 | C38: =SUMPRODUCT((TEXT(Detalle!B2:B101,"YYYY-MM")="2025-07")*(Detalle!C2:C101="Reclamo")) -> 7 | D38: =SUMPRODUCT((TEXT(Detalle!B2:B101,"YYYY-MM")="2025-07")*(Detalle!C2:C101="Queja")) -> 4 | E38: =SUMPRODUCT((TEXT(Detalle!B2:B101,"YYYY-MM")="2025-07")*Detalle!N2:N101) -> 1967000
A39: Agosto | B39: =SUMPRODUCT((TEXT(Detalle!B2:B101,"YYYY-MM")="2025-08")*1) -> 14 | C39: =SUMPRODUCT((TEXT(Detalle!B2:B101,"YYYY-MM")="2025-08")*(Detalle!C2:C101="Reclamo")) -> 6 | D39: =SUMPRODUCT((TEXT(Detalle!B2:B101,"YYYY-MM")="2025-08")*(Detalle!C2:C101="Queja")) -> 6 | E39: =SUMPRODUCT((TEXT(Detalle!B2:B101,"YYYY-MM")="2025-08")*Detalle!N2:N101) -> 2106000
A42: Nota: datos simulados con fines de demostración / analítica del programa Master IA Local. No corresponden a PQRS reales de Andina Foods S.A.S.
