Workbook

Sheet Productos
A1: SKU | B1: Nombre Producto | C1: Categoría | D1: Marca | E1: Proveedor | F1: Unidad | G1: Precio Costo (COP) | H1: Precio Venta (COP) | I1: Margen % | J1: Stock Actual (unid.) | K1: Stock Mínimo (unid.) | L1: Rotación (veces/año) | M1: Último Movimiento | N1: Estado
A2: P001 | B2: Leche Condensada Lata 380g | C2: Alimentos | D2: Kraft | E2: Postobón S.A. | F2: Unidad | G2: 4420 | H2: 5680 | I2: =(H2-G2)/H2 -> 0.22183099 | J2: 1530 | K2: 294 | L2: 21 | M2: 45911 | N2: Activo
A3: P002 | B3: Crema Dental Tubo 90g | C3: Cuidado Personal | D3: Colgate-Palmolive | E3: Grupo Familia S.A. | F3: Unidad | G3: 4190 | H3: 7280 | I3: =(H3-G3)/H3 -> 0.42445055 | J3: 136 | K3: 244 | L3: 5 | M3: 45752 | N3: Descontinuado
A4: P003 | B4: Yogurt Bebible Fresa 200ml | C4: Bebidas | D4: Coca-Cola | E4: Postobón S.A. | F4: Caja | G4: 7300 | H4: 9460 | I4: =(H4-G4)/H4 -> 0.22832981 | J4: 3654 | K4: 386 | L4: 48 | M4: 45951 | N4: Activo
A5: P004 | B5: Arroz Blanco Bolsa 1kg | C5: Alimentos | D5: Alpina | E5: Postobón S.A. | F5: Caja | G5: 3500 | H5: 4850 | I5: =(H5-G5)/H5 -> 0.27835052 | J5: 586 | K5: 156 | L5: 23 | M5: 45914 | N5: Activo
A6: P005 | B6: Gaseosa Sabor Cola 2.5L | C6: Bebidas | D6: Coca-Cola | E6: Postobón S.A. | F6: Caja | G6: 5300 | H6: 6290 | I6: =(H6-G6)/H6 -> 0.15739269 | J6: 129 | K6: 292 | L6: 30 | M6: 45897 | N6: En falta
A7: P006 | B7: Panela Bloque 1kg | C7: Alimentos | D7: Nestlé | E7: Nestlé de Colombia S.A. | F7: Paquete | G7: 11930 | H7: 15430 | I7: =(H7-G7)/H7 -> 0.22683085 | J7: 87 | K7: 143 | L7: 24 | M7: 45998 | N7: En falta
A8: P007 | B8: Chocolate de Mesa Barra 500g | C8: Alimentos | D8: Alpina | E8: Alpina Productos Alimenticios | F8: Unidad | G8: 1740 | H8: 2400 | I8: =(H8-G8)/H8 -> 0.275 | J8: 396 | K8: 175 | L8: 25 | M8: 45998 | N8: Activo
A9: P008 | B9: Snack de Papa Bolsa 150g | C9: Marca propia | D9: Andina Selecta | E9: Andina Selecta (producción propia) | F9: Unidad | G9: 10560 | H9: 18190 | I9: =(H9-G9)/H9 -> 0.41946124 | J9: 3200 | K9: 287 | L9: 11 | M9: 45999 | N9: Activo
A10: P009 | B10: Desodorante en Aerosol Frasco 150ml | C10: Cuidado Personal | D10: Colgate-Palmolive | E10: Grupo Familia S.A. | F10: Unidad | G10: 16900 | H10: 29270 | I10: =(H10-G10)/H10 -> 0.42261701 | J10: 126 | K10: 216 | L10: 12 | M10: 45900 | N10: En falta
A11: P010 | B11: Café Instantáneo Frasco 170g | C11: Bebidas | D11: Postobón | E11: Alpina Productos Alimenticios | F11: Caja | G11: 2810 | H11: 3600 | I11: =(H11-G11)/H11 -> 0.21944444 | J11: 3191 | K11: 328 | L11: 51 | M11: 45947 | N11: Activo
A12: P011 | B12: Agua Sin Gas 600ml | C12: Marca propia | D12: Andina Selecta | E12: Andina Selecta (producción propia) | F12: Litro | G12: 2590 | H12: 4110 | I12: =(H12-G12)/H12 -> 0.36982968 | J12: 434 | K12: 419 | L12: 18 | M12: 45962 | N12: Activo
A13: P012 | B13: Salchicha Tipo Viena Paquete 500g | C13: Alimentos | D13: Kraft | E13: Postobón S.A. | F13: Unidad | G13: 4990 | H13: 6740 | I13: =(H13-G13)/H13 -> 0.25964392 | J13: 997 | K13: 302 | L13: 35 | M13: 45993 | N13: Activo
... A121: P120 | B121: Jugo de Naranja Natural 1L (54) | C121: Bebidas | D121: Alpina | E121: Alpina Productos Alimenticios | F121: Paquete | G121: 1540 | H121: 2020 | I121: =(H121-G121)/H121 -> 0.23762376 | J121: 4532 | K121: 350 | L121: 43 | M121: 46013 | N121: Activo
A123: Supuestos: Precio Costo y Precio Venta son valores de entrada (fuente: simulación para demo/analítica, no datos reales de Andina Foods S.A.S.). Margen % = (Precio Venta - Precio Costo) / Precio Venta. Estado 'En falta' = Stock Actual por debajo de Stock Mínimo.

Sheet Resumen
A1: Resumen Ejecutivo — Portafolio de Productos Andina Foods
A3: Total de SKUs | B3: =COUNTA(Productos!A2:A121) -> 120
A4: Productos Activos | B4: =COUNTIF(Productos!N2:N121,"Activo") -> 90
A5: Productos En falta | B5: =COUNTIF(Productos!N2:N121,"En falta") -> 18
A6: Productos Descontinuados | B6: =COUNTIF(Productos!N2:N121,"Descontinuado") -> 12
A8: Bebidas (# SKUs) | B8: =COUNTIF(Productos!C2:C121,"Bebidas") -> 39
A9: Alimentos (# SKUs) | B9: =COUNTIF(Productos!C2:C121,"Alimentos") -> 37
A10: Aseo (# SKUs) | B10: =COUNTIF(Productos!C2:C121,"Aseo") -> 14
A11: Cuidado Personal (# SKUs) | B11: =COUNTIF(Productos!C2:C121,"Cuidado Personal") -> 12
A12: Marca propia (# SKUs) | B12: =COUNTIF(Productos!C2:C121,"Marca propia") -> 18
A14: Margen % promedio (todos los productos) | B14: =AVERAGE(Productos!I2:I121) -> 0.26949775
A15: Margen % promedio — Bebidas | B15: =AVERAGEIF(Productos!C2:C121,"Bebidas",Productos!I2:I121) -> 0.20194143
A16: Margen % promedio — Alimentos | B16: =AVERAGEIF(Productos!C2:C121,"Alimentos",Productos!I2:I121) -> 0.23278208
A17: Margen % promedio — Aseo | B17: =AVERAGEIF(Productos!C2:C121,"Aseo",Productos!I2:I121) -> 0.29603838
A18: Margen % promedio — Cuidado Personal | B18: =AVERAGEIF(Productos!C2:C121,"Cuidado Personal",Productos!I2:I121) -> 0.37609399
A19: Margen % promedio — Marca propia | B19: =AVERAGEIF(Productos!C2:C121,"Marca propia",Productos!I2:I121) -> 0.39963397
A21: Rotación promedio (veces/año) | B21: =AVERAGE(Productos!L2:L121) -> 21.675
A22: Valor de inventario a costo (COP) | B22: =SUMPRODUCT(Productos!G2:G121,Productos!J2:J121) -> 1469784130
A23: Valor de inventario a precio venta (COP) | B23: =SUMPRODUCT(Productos!H2:H121,Productos!J2:J121) -> 2073004100
A25: Top 10 Productos Más Rentables (Margen %)
A26: SKU | B26: Producto | C26: Categoría | D26: Margen %
A27: P057 | B27: Shampoo Anticaspa Botella 400ml | C27: Cuidado Personal | D27: =Productos!I58 -> 0.43358634
A28: P029 | B28: Toallas Higiénicas Paquete x10 | C28: Cuidado Personal | D28: =Productos!I30 -> 0.43210377
A29: P064 | B29: Jabón en Barra Multiusos Barra 300g | C29: Marca propia | D29: =Productos!I65 -> 0.43004587
A30: P037 | B30: Jugo de Naranja Natural 200ml | C30: Marca propia | D30: =Productos!I38 -> 0.42664872
A31: P015 | B31: Jugo de Naranja Natural 1L | C31: Marca propia | D31: =Productos!I16 -> 0.42620865
A32: P051 | B32: Esponja Multiusos Paquete x3 | C32: Marca propia | D32: =Productos!I52 -> 0.42478713
A33: P002 | B33: Crema Dental Tubo 90g | C33: Cuidado Personal | D33: =Productos!I3 -> 0.42445055
A34: P009 | B34: Desodorante en Aerosol Frasco 150ml | C34: Cuidado Personal | D34: =Productos!I10 -> 0.42261701
A35: P008 | B35: Snack de Papa Bolsa 150g | C35: Marca propia | D35: =Productos!I9 -> 0.41946124
A36: P112 | B36: Agua Saborizada Limón 500ml (18) | C36: Marca propia | D36: =Productos!I113 -> 0.41638608
A38: Productos en Falta (Stock Actual < Stock Mínimo)
A39: SKU | B39: Producto | C39: Stock Actual | D39: Stock Mínimo
A40: =Productos!A6 -> P005 | B40: =Productos!B6 -> Gaseosa Sabor Cola 2.5L | C40: =Productos!J6 -> 129 | D40: =Productos!K6 -> 292
A41: =Productos!A7 -> P006 | B41: =Productos!B7 -> Panela Bloque 1kg | C41: =Productos!J7 -> 87 | D41: =Productos!K7 -> 143
A42: =Productos!A10 -> P009 | B42: =Productos!B10 -> Desodorante en Aerosol Frasco 150ml | C42: =Productos!J10 -> 126 | D42: =Productos!K10 -> 216
A43: =Productos!A18 -> P017 | B43: =Productos!B18 -> Bebida Energizante 250ml | C43: =Productos!J18 -> 286 | D43: =Productos!K18 -> 497
A44: =Productos!A21 -> P020 | B44: =Productos!B21 -> Blanqueador Líquido Botella 1L | C44: =Productos!J21 -> 341 | D44: =Productos!K21 -> 349
A45: =Productos!A23 -> P022 | B45: =Productos!B23 -> Mayonesa Frasco 400g | C45: =Productos!J23 -> 58 | D45: =Productos!K23 -> 132
A46: =Productos!A30 -> P029 | B46: =Productos!B30 -> Toallas Higiénicas Paquete x10 | C46: =Productos!J30 -> 97 | D46: =Productos!K30 -> 128
...
