Workbook

Sheet Proyectos
A1: ID Proyecto | B1: Nombre | C1: Categoría | D1: Objetivo | E1: Departamento Responsable | F1: Líder Proyecto | G1: Fecha Inicio | H1: Fecha Fin Planificada | I1: Avance % | J1: Estado | K1: Presupuesto (COP) | L1: % Gastado | M1: Gastado a la Fecha (COP) | N1: Beneficio Anual Esperado (COP) | O1: ROI % Anual | P1: Nivel de Riesgo | Q1: Próximo Hito | R1: Indicador KPI Principal
A2: PROY-001 | B2: Optimización de Rutas de Distribución | C2: Operacional | D2: Rediseñar las rutas de reparto en Barranquilla y Cartagena para reducir kilómetros recorridos y tiempos muertos de la flota. | E2: Logística y Distribución | F2: María Núñez Romero | G2: 45536 | H2: 46022 | I2: 0.65 | J2: En ejecución | K2: 180000000 | L2: 0.62 | M2: =K2*L2 -> 111600000 | N2: 420000000 | O2: =N2/K2 -> 2.3333333 | P2: Bajo | Q2: 30/10/2025: Rollout completo de rutas optimizadas en las 2 ciudades | R2: Costo de flete por unidad entregada (COP/unidad)
A3: PROY-002 | B3: Implementación de WMS y Automatización de Bodega | C3: Operacional | D3: Implementar un sistema de gestión de bodega (WMS) que automatice el control de inventario y ubicación de productos. | E3: Bodega y Almacén | F3: Wilson Pacheco Redondo | G3: 45597 | H3: 45961 | I3: 0.4 | J3: En riesgo | K3: 320000000 | L3: 0.55 | M3: =K3*L3 -> 176000000 | N3: 480000000 | O3: =N3/K3 -> 1.5 | P3: Alto | Q3: 15/09/2025: Integración crítica con el ERP financiero | R3: Precisión de inventario (% de exactitud)
A4: PROY-003 | B4: Programa de Reducción de Mermas en Bodega | C4: Operacional | D4: Disminuir las pérdidas por vencimiento, daño y manejo inadecuado en las bodegas regionales. | E4: Bodega y Almacén | F4: Wilson Pacheco Redondo | G4: 45672 | H4: 46006 | I4: 0.55 | J4: En ejecución | K4: 90000000 | L4: 0.5 | M4: =K4*L4 -> 45000000 | N4: 150000000 | O4: =N4/K4 -> 1.6666667 | P4: Medio | Q4: 20/09/2025: Auditoría de mermas del tercer trimestre | R4: % de mermas sobre inventario total
A5: PROY-004 | B5: Optimización de Compras y Proveedores | C5: Operacional | D5: Consolidar proveedores estratégicos y renegociar condiciones de compra para mejorar el costo de abastecimiento. | E5: Compras | F5: Alejandra Padilla Rojas | G5: 45444 | H5: 45838 | I5: 1 | J5: Completado | K5: 60000000 | L5: 0.98 | M5: =K5*L5 -> 58800000 | N5: 140000000 | O5: =N5/K5 -> 2.3333333 | P5: Bajo | Q5: 30/06/2025: Cierre y evaluación de resultados (proyecto finalizado) | R5: Costo promedio de abastecimiento por SKU
A6: PROY-005 | B6: Mejora de Tiempos de Entrega Última Milla | C6: Operacional | D6: Reducir el tiempo promedio de entrega al cliente final mediante renovación de flota y microcentros de despacho. | E6: Logística y Distribución | F6: María Núñez Romero | G6: 45689 | H6: 46053 | I6: 0.25 | J6: Pausado | K6: 150000000 | L6: 0.2 | M6: =K6*L6 -> 30000000 | N6: 260000000 | O6: =N6/K6 -> 1.7333333 | P6: Alto | Q6: 15/01/2026: Reactivación una vez aprobado el presupuesto de flota adicional | R6: Tiempo promedio de entrega (horas)
A7: PROY-006 | B7: Expansión Comercial a Santa Marta y Valledupar | C7: Comercial | D7: Abrir un punto de distribución y equipo comercial dedicado en las zonas del Magdalena y Cesar. | E7: Ventas | F7: Eduardo Jiménez Torres | G7: 45566 | H7: 46022 | I7: 0.45 | J7: En riesgo | K7: 280000000 | L7: 0.6 | M7: =K7*L7 -> 168000000 | N7: 700000000 | O7: =N7/K7 -> 2.5 | P7: Crítico | Q7: 30/10/2025: Apertura del punto de distribución en Valledupar (retrasada 2 meses) | R7: Nuevos clientes activos por zona
A8: PROY-007 | B8: Programa de Fidelización de Clientes | C8: Comercial | D8: Diseñar un programa de puntos y beneficios para tenderos y supermercados que aumente la recompra. | E8: Servicio al Cliente | F8: Yolanda Vargas Medina | G8: 45717 | H8: 45991 | I8: 0.3 | J8: Pausado | K8: 70000000 | L8: 0.28 | M8: =K8*L8 -> 19600000 | N8: 130000000 | O8: =N8/K8 -> 1.8571429 | P8: Medio | Q8: 30/11/2025: Reanudación sujeta a disponibilidad de equipo de TI | R8: Tasa de retención de clientes
A9: PROY-008 | B9: Relanzamiento de Marca Propia Andina Selecta | C9: Comercial | D9: Renovar empaque, mezcla de producto y campaña de marca propia para aumentar su participación en ventas. | E9: Mercadeo | F9: Édgar Rojas Redondo | G9: 45505 | H9: 45930 | I9: 0.8 | J9: En ejecución | K9: 130000000 | L9: 0.85 | M9: =K9*L9 -> 110500000 | N9: 260000000 | O9: =N9/K9 -> 2 | P9: Medio | Q9: 30/09/2025: Campaña de lanzamiento nacional | R9: Participación de marca propia en ventas totales (%)
A10: PROY-009 | B10: Fortalecimiento del Canal Institucional | C10: Comercial | D10: Desarrollar una oferta y equipo dedicado para colegios, clínicas, hoteles y restaurantes. | E10: Ventas | F10: Eduardo Jiménez Torres | G10: 45901 | H10: 46203 | I10: 0.08 | J10: Planificación | K10: 95000000 | L10: 0.06 | M10: =K10*L10 -> 5700000 | N10: 190000000 | O10: =N10/K10 -> 2 | P10: Bajo | Q10: 15/10/2025: Aprobación del plan comercial y primeros contactos institucionales | R10: N° de clientes institucionales activos
A11: PROY-010 | B11: Implementación de ERP Corporativo | C11: Tecnológico | D11: Reemplazar los sistemas aislados de ventas, bodega y contabilidad por un ERP integrado. | E11: Tecnología (TI) | F11: Diana Muñoz Rodríguez | G11: 45413 | H11: 46022 | I11: 0.55 | J11: En riesgo | K11: 480000000 | L11: 0.68 | M11: =K11*L11 -> 326400000 | N11: 620000000 | O11: =N11/K11 -> 1.2916667 | P11: Crítico | Q11: 30/11/2025: Go-live del módulo financiero y de inventarios | R11: Tiempo de cierre contable mensual (días)
A12: PROY-011 | B12: Automatización de Facturación Electrónica y Cobranza Digital | C12: Tecnológico | D12: Automatizar la emisión de facturas electrónicas y habilitar cobro digital para reducir cartera vencida. | E12: Tecnología (TI) | F12: Diana Muñoz Rodríguez | G12: 45689 | H12: 45961 | I12: 0.5 | J12: En ejecución | K12: 85000000 | L12: 0.45 | M12: =K12*L12 -> 38250000 | N12: 170000000 | O12: =N12/K12 -> 2 | P12: Medio | Q12: 31/08/2025: Integración con la DIAN en producción | R12: Días promedio de cobro (DSO)
A13: PROY-012 | B13: Dashboard de Business Intelligence Comercial y Logístico | C13: Tecnológico | D13: Construir tableros de control con datos de ventas, cartera e inventario para la toma de decisiones gerenciales. | E13: Tecnología (TI) | F13: Diana Muñoz Rodríguez | G13: 45748 | H13: 46022 | I13: 0.2 | J13: En riesgo | K13: 60000000 | L13: 0.32 | M13: =K13*L13 -> 19200000 | N13: 90000000 | O13: =N13/K13 -> 1.5 | P13: Alto | Q13: 31/10/2025: MVP con datos de ventas y logística | R13: Tiempo de generación de reportes gerenciales (horas)
... A15: PROY-014 | B15: Plan de Bienestar y Retención de Personal | C15: RRHH | D15: Reducir la rotación de personal operativo mediante beneficios, bienestar y plan de carrera. | E15: Recursos Humanos | F15: Hernán Mendoza Romero | G15: 45536 | H15: 45930 | I15: 0.9 | J15: En ejecución | K15: 50000000 | L15: 0.85 | M15: =K15*L15 -> 42500000 | N15: 100000000 | O15: =N15/K15 -> 2 | P15: Bajo | Q15: 30/09/2025: Evaluación de impacto en la tasa de rotación | R15: Tasa de rotación de personal operativo (%)
A17: Supuestos: Avance %, % Gastado, Presupuesto y Beneficio Anual Esperado son valores de entrada (simulación para demo/analítica, no datos reales de Andina Foods S.A.S.). Gastado a la Fecha = Presupuesto × % Gastado. ROI % Anual = Beneficio Anual Esperado / Presupuesto. Líder Proyecto y Departamento Responsable son consistentes con Evaluaciones_Desempeno_Andina_Foods.xlsx.

Sheet Resumen
A1: Resumen — Portafolio de Proyectos Andina Foods 2025
A3: Total de proyectos activos | B3: =COUNTA(Proyectos!A2:A15) -> 14
A5: En ejecución | B5: =COUNTIF(Proyectos!J2:J15,"En ejecución") -> 6
A6: En riesgo | B6: =COUNTIF(Proyectos!J2:J15,"En riesgo") -> 4
A7: Pausados | B7: =COUNTIF(Proyectos!J2:J15,"Pausado") -> 2
A8: Planificación | B8: =COUNTIF(Proyectos!J2:J15,"Planificación") -> 1
A9: Completados | B9: =COUNTIF(Proyectos!J2:J15,"Completado") -> 1
A11: Operacionales (# proyectos) | B11: =COUNTIF(Proyectos!C2:C15,"Operacional") -> 5
A12: Comerciales (# proyectos) | B12: =COUNTIF(Proyectos!C2:C15,"Comercial") -> 4
A13: Tecnológicos (# proyectos) | B13: =COUNTIF(Proyectos!C2:C15,"Tecnológico") -> 3
A14: RRHH (# proyectos) | B14: =COUNTIF(Proyectos!C2:C15,"RRHH") -> 2
A16: Presupuesto total del portafolio (COP) | B16: =SUM(Proyectos!K2:K15) -> 2105000000
A17: Gastado a la fecha (COP) | B17: =SUM(Proyectos!M2:M15) -> 1179050000
A18: % Ejecución presupuestal del portafolio | B18: =B17/B16 -> 0.56011876
A19: Beneficio anual esperado total (COP) | B19: =SUM(Proyectos!N2:N15) -> 3840000000
A20: ROI % promedio ponderado del portafolio | B20: =B19/B16 -> 1.824228
A22: Proyectos con riesgo Crítico o Alto | B22: =COUNTIF(Proyectos!P2:P15,"Crítico")+COUNTIF(Proyectos!P2:P15,"Alto") -> 5
A24: Proyectos en Riesgo / Riesgo Crítico-Alto (Alertas)
A25: ID | B25: Nombre | C25: Estado | D25: Nivel de Riesgo | E25: Líder | F25: Avance %
A26: =Proyectos!A3 -> PROY-002 | B26: =Proyectos!B3 -> Implementación de WMS y Automatización de Bodega | C26: =Proyectos!J3 -> En riesgo | D26: =Proyectos!P3 -> Alto | E26: =Proyectos!F3 -> Wilson Pacheco Redondo | F26: =Proyectos!I3 -> 0.4
A27: =Proyectos!A6 -> PROY-005 | B27: =Proyectos!B6 -> Mejora de Tiempos de Entrega Última Milla | C27: =Proyectos!J6 -> Pausado | D27: =Proyectos!P6 -> Alto | E27: =Proyectos!F6 -> María Núñez Romero | F27: =Proyectos!I6 -> 0.25
A28: =Proyectos!A7 -> PROY-006 | B28: =Proyectos!B7 -> Expansión Comercial a Santa Marta y Valledupar | C28: =Proyectos!J7 -> En riesgo | D28: =Proyectos!P7 -> Crítico | E28: =Proyectos!F7 -> Eduardo Jiménez Torres | F28: =Proyectos!I7 -> 0.45
A29: =Proyectos!A11 -> PROY-010 | B29: =Proyectos!B11 -> Implementación de ERP Corporativo | C29: =Proyectos!J11 -> En riesgo | D29: =Proyectos!P11 -> Crítico | E29: =Proyectos!F11 -> Diana Muñoz Rodríguez | F29: =Proyectos!I11 -> 0.55
A30: =Proyectos!A13 -> PROY-012 | B30: =Proyectos!B13 -> Dashboard de Business Intelligence Comercial y Logístico | C30: =Proyectos!J13 -> En riesgo | D30: =Proyectos!P13 -> Alto | E30: =Proyectos!F13 -> Diana Muñoz Rodríguez | F30: =Proyectos!I13 -> 0.2
A33: Proyectos Ordenados por ROI % Esperado (mayor a menor)
A34: ID | B34: Nombre | C34: Categoría | D34: Presupuesto (COP) | E34: Beneficio Anual (COP) | F34: ROI %
A35: =Proyectos!A7 -> PROY-006 | B35: =Proyectos!B7 -> Expansión Comercial a Santa Marta y Valledupar | C35: =Proyectos!C7 -> Comercial | D35: =Proyectos!K7 -> 280000000 | E35: =Proyectos!N7 -> 700000000 | F35: =Proyectos!O7 -> 2.5
A36: =Proyectos!A14 -> PROY-013 | B36: =Proyectos!B14 -> Programa de Capacitación y Desarrollo de Talento | C36: =Proyectos!C14 -> RRHH | D36: =Proyectos!K14 -> 55000000 | E36: =Proyectos!N14 -> 130000000 | F36: =Proyectos!O14 -> 2.3636364
A37: =Proyectos!A2 -> PROY-001 | B37: =Proyectos!B2 -> Optimización de Rutas de Distribución | C37: =Proyectos!C2 -> Operacional | D37: =Proyectos!K2 -> 180000000 | E37: =Proyectos!N2 -> 420000000 | F37: =Proyectos!O2 -> 2.3333333
A38: =Proyectos!A5 -> PROY-004 | B38: =Proyectos!B5 -> Optimización de Compras y Proveedores | C38: =Proyectos!C5 -> Operacional | D38: =Proyectos!K5 -> 60000000 | E38: =Proyectos!N5 -> 140000000 | F38: =Proyectos!O5 -> 2.3333333
A39: =Proyectos!A9 -> PROY-008 | B39: =Proyectos!B9 -> Relanzamiento de Marca Propia Andina Selecta | C39: =Proyectos!C9 -> Comercial | D39: =Proyectos!K9 -> 130000000 | E39: =Proyectos!N9 -> 260000000 | F39: =Proyectos!O9 -> 2
A40: =Proyectos!A10 -> PROY-009 | B40: =Proyectos!B10 -> Fortalecimiento del Canal Institucional | C40: =Proyectos!C10 -> Comercial | D40: =Proyectos!K10 -> 95000000 | E40: =Proyectos!N10 -> 190000000 | F40: =Proyectos!O10 -> 2
A41: =Proyectos!A12 -> PROY-011 | B41: =Proyectos!B12 -> Automatización de Facturación Electrónica y Cobranza Digital | C41: =Proyectos!C12 -> Tecnológico | D41: =Proyectos!K12 -> 85000000 | E41: =Proyectos!N12 -> 170000000 | F41: =Proyectos!O12 -> 2
A42: =Proyectos!A15 -> PROY-014 | B42: =Proyectos!B15 -> Plan de Bienestar y Retención de Personal | C42: =Proyectos!C15 -> RRHH | D42: =Proyectos!K15 -> 50000000 | E42: =Proyectos!N15 -> 100000000 | F42: =Proyectos!O15 -> 2
A43: =Proyectos!A8 -> PROY-007 | B43: =Proyectos!B8 -> Programa de Fidelización de Clientes | C43: =Proyectos!C8 -> Comercial | D43: =Proyectos!K8 -> 70000000 | E43: =Proyectos!N8 -> 130000000 | F43: =Proyectos!O8 -> 1.8571429
A44: =Proyectos!A6 -> PROY-005 | B44: =Proyectos!B6 -> Mejora de Tiempos de Entrega Última Milla | C44: =Proyectos!C6 -> Operacional | D44: =Proyectos!K6 -> 150000000 | E44: =Proyectos!N6 -> 260000000 | F44: =Proyectos!O6 -> 1.7333333
A45: =Proyectos!A4 -> PROY-003 | B45: =Proyectos!B4 -> Programa de Reducción de Mermas en Bodega | C45: =Proyectos!C4 -> Operacional | D45: =Proyectos!K4 -> 90000000 | E45: =Proyectos!N4 -> 150000000 | F45: =Proyectos!O4 -> 1.6666667
A46: =Proyectos!A3 -> PROY-002 | B46: =Proyectos!B3 -> Implementación de WMS y Automatización de Bodega | C46: =Proyectos!C3 -> Operacional | D46: =Proyectos!K3 -> 320000000 | E46: =Proyectos!N3 -> 480000000 | F46: =Proyectos!O3 -> 1.5
A47: =Proyectos!A13 -> PROY-012 | B47: =Proyectos!B13 -> Dashboard de Business Intelligence Comercial y Logístico | C47: =Proyectos!C13 -> Tecnológico | D47: =Proyectos!K13 -> 60000000 | E47: =Proyectos!N13 -> 90000000 | F47: =Proyectos!O13 -> 1.5
A48: =Proyectos!A11 -> PROY-010 | B48: =Proyectos!B11 -> Implementación de ERP Corporativo | C48: =Proyectos!C11 -> Tecnológico | D48: =Proyectos!K11 -> 480000000 | E48: =Proyectos!N11 -> 620000000 | F48: =Proyectos!O11 -> 1.2916667
...
